Workbook

Sheet Revision History
A2: Halo Microelectronics Co., Ltd. HL-TE-B10-R02 V05
A3: Version | B3: PGM_NAME | C3: Release Date | D3: Author | E3: Description of Modification
A4: V01 | B4: HL5083CP00_203KM_A00_V01 | C4: 46026 | D4: Hongen.liu | E4: Change for BC Version. add SNK_RCP_trim/SBU_leakage/SBU_Clapm/SBU_Ron test.
A5: V02 | B5: HL5083CP00_203KM_A00_V02 | C5: 46029 | D5: Hongen.liu | E5: add RCP_trim in code
A6: V03 | B6: HL5083CP00_203KM_A00_V03 | C6: 46038 | D6: Hongen.liu | E6: modify the limits after 16pcsw wafer. and remove the 0.4V_SBU_Ron test.
A7: V04 | B7: HL5083CP00_204KM_A00_V04 | C7: 46041 | D7: Hongen.liu | E7: add RCP trim_table for BD version
A8: V05 | B8: HL5083CP00_204KM_A00_V05 | C8: 46107 | D8: Hongen.liu | E8: modify LDO trim target to 3.15V and update limits.
A9: V06 | B9: HL5083CP00_204KM_A00_V06 | C9: 46139 | D9: Hongen.liu | E9: add the SRC_Sat trim in code and do TTR

Sheet Datasheet vs Test Item
A1: Halo Microelectronics Co., Ltd. HL-TE-B10-R02 V05
A2: HL5083A-BD Datasheet vs Test Item Coverage
A3: Datasheet | H3: ATE Test Spec
A4: Symbol | B4: Parameter | C4: Condition | D4: Min | E4: Typ | F4: Max | G4: Unit | H4: Coveraged? | I4: Symbol | J4: Min | K4: Max | L4: Unit | M4: Remark
A5: Power Supplies
A6: IQ_STBY_VIN3V3 | B6: Quiescent Current for VIN_3V3 at Stand-by mode with I2C active | C6: Device in the delink mode where VIN_3V3=3.3V, VBUS_P0=VBUS_P1=0V, LDO3V3=OFF, all CC1/2_P0/1 switches stay on, all the other switches stay off, I2C active, all the others are set to default, the internal switch in ideal diode mode | E6: 85 | F6: 110 | G6: µA | H6: Y | I6: IQ_STBY_VIN3V3 | J6: =IF(I6<>"",VLOOKUP(I6,'Test Item'!C:H,2,0),"") -> 60 | K6: =IF(I6<>"",VLOOKUP(I6,'Test Item'!C:H,3,0),"") -> 95 | L6: =IF(I6<>"",VLOOKUP(I6,'Test Item'!C:H,4,0),"") -> uA
A7: IQ_SNK_VIN3V3 | B7: Quiescent Current for VIN_3V3 in sink mode enabled | C7: VBUS_P0 or P1=5V, VIN_3V3=3.3V, one SNK_CTL_P0/P1=ON with the high voltage output, LDO3V3=OFF, all the other switches stay off, except for all CC1/2_P0/1 switches, all the others are set to default | E7: 185 | F7: 220 | G7: µA | H7: Y | I7: IQ_SNK_VIN3V3 | J7: =IF(I7<>"",VLOOKUP(I7,'Test Item'!C:H,2,0),"") -> 170 | K7: =IF(I7<>"",VLOOKUP(I7,'Test Item'!C:H,3,0),"") -> 217 | L7: =IF(I7<>"",VLOOKUP(I7,'Test Item'!C:H,4,0),"") -> uA
A8: IQ_SNK_VBUS | B8: Quiescent Current for VBUS_P0/P1 in sink mode enabled | C8: VBUS_P0 or P1=5V, VIN_3V3=3.3V, one SNK_CTL_P0/P1=ON with the high voltage output, LDO3V3=OFF, all the other switches stay off, except for all CC1/2_P0/1 switches, all the others are set to default | E8: 310 | F8: 360 | G8: µA | H8: Y | I8: IQ_SNK_VBUS_P0 | J8: =IF(I8<>"",VLOOKUP(I8,'Test Item'!C:H,2,0),"") -> 260 | K8: =IF(I8<>"",VLOOKUP(I8,'Test Item'!C:H,3,0),"") -> 355 | L8: =IF(I8<>"",VLOOKUP(I8,'Test Item'!C:H,4,0),"") -> uA
A9: IQ_SRC_VIN3V3 | B9: Quiescent Current for VIN_3V3 in source mode enabled with no load | C9: V5V=5V, VIN_3V3=3.3V, one Source SW=ON, LDO3V3=OFF, all the other switches stay off, except for all CC1/2_P0/1 switches, all the others are set to default | E9: 260 | F9: 330 | G9: µA | H9: Y | I9: IQ_SRC_VIN3V3_VBUS_P0 | J9: =IF(I9<>"",VLOOKUP(I9,'Test Item'!C:H,2,0),"") -> 225 | K9: =IF(I9<>"",VLOOKUP(I9,'Test Item'!C:H,3,0),"") -> 325 | L9: =IF(I9<>"",VLOOKUP(I9,'Test Item'!C:H,4,0),"") -> uA
A10: IQ_SRC_V5V | B10: Quiescent Current for V5V in source mode enabled | C10: V5V=5V, VIN_3V3=3.3V, one Source SW=ON, LDO3V3=OFF, all the other switches stay off, except for all CC1/2_P0/1 switches, all the others are set to default | E10: 220 | F10: 280 | G10: µA | H10: Y | I10: IQ_SRC_V5V_VBUS_P0 | J10: =IF(I10<>"",VLOOKUP(I10,'Test Item'!C:H,2,0),"") -> 190 | K10: =IF(I10<>"",VLOOKUP(I10,'Test Item'!C:H,3,0),"") -> 250 | L10: =IF(I10<>"",VLOOKUP(I10,'Test Item'!C:H,4,0),"") -> uA
A11: IQ_VCONN_V5V | B11: Quiescent Current for V5V in VCONN mode enabled | C11: V5V=5V, VIN_3V3=3.3V, one VCONN SW=ON at one Port only, LDO3V3=OFF, all the other switches stay off, except for all CC1/2_P0/1 switches, all the others are set to default | E11: 50 | F11: 65 | G11: µA | H11: Y | I11: IQ_VCONN_V5V_CC1_P0 | J11: =IF(I11<>"",VLOOKUP(I11,'Test Item'!C:H,2,0),"") -> 30 | K11: =IF(I11<>"",VLOOKUP(I11,'Test Item'!C:H,3,0),"") -> 63 | L11: =IF(I11<>"",VLOOKUP(I11,'Test Item'!C:H,4,0),"") -> uA
A12: VVIN_3V3_UVLO | B12: VIN_3V3 UVLO | C12: Rising for VIN_3V3_POK=H | D12: 2.35 | E12: 2.5 | F12: 2.65 | G12: V | H12: Y | I12: VIN3V3_UVLO_RISE | J12: =IF(I12<>"",VLOOKUP(I12,'Test Item'!C:H,2,0),"") -> 2.36 | K12: =IF(I12<>"",VLOOKUP(I12,'Test Item'!C:H,3,0),"") -> 2.64 | L12: =IF(I12<>"",VLOOKUP(I12,'Test Item'!C:H,4,0),"") -> V
A13: VVIN_3V3_UVLO_HYS | B13: VIN_3V3 UVLO Hysteresis | C13: Falling | E13: 200 | G13: mV | H13: Y | I13: VIN3V3_UVLO_HYS | J13: =IF(I13<>"",VLOOKUP(I13,'Test Item'!C:H,2,0),"") -> 0.1 | K13: =IF(I13<>"",VLOOKUP(I13,'Test Item'!C:H,3,0),"") -> 0.45 | L13: =IF(I13<>"",VLOOKUP(I13,'Test Item'!C:H,4,0),"") -> V
A14: 3.3V LDO Regulator (LDO3V3) | J14: =IF(I14<>"",VLOOKUP(I14,'Test Item'!C:H,2,0),"") | K14: =IF(I14<>"",VLOOKUP(I14,'Test Item'!C:H,3,0),"") | L14: =IF(I14<>"",VLOOKUP(I14,'Test Item'!C:H,4,0),"")
A15: VLDO3V3(NOTE2) | B15: LDO3V3 output regulation voltage | C15: VBUS_P0/P1 ≥ UVLO, ILOAD=0mA-60mA | D15: -0.03 | E15: 3.1 | F15: 0.03 | G15: V | H15: Y | I15: LDO_REG_28V_5MA | J15: =IF(I15<>"",VLOOKUP(I15,'Test Item'!C:H,2,0),"") -> 3.05 | K15: =IF(I15<>"",VLOOKUP(I15,'Test Item'!C:H,3,0),"") -> 3.19 | L15: =IF(I15<>"",VLOOKUP(I15,'Test Item'!C:H,4,0),"") -> V | M15: 按3%的话是(3.007,3.193)V
A16: ILDO3V3_MAX | B16: LDO3V3 maximum output current | C16: DC continuous | D16: 60 | G16: mA | H16: Y | I16: LDO_REG_28V_30MA | J16: =IF(I16<>"",VLOOKUP(I16,'Test Item'!C:H,2,0),"") -> 3.05 | K16: =IF(I16<>"",VLOOKUP(I16,'Test Item'!C:H,3,0),"") -> 3.19 | L16: =IF(I16<>"",VLOOKUP(I16,'Test Item'!C:H,4,0),"") -> V
A17: ILDO3V3_LIM | B17: LDO3V3 Current Limit | C17: VLDO3V3=0V | D17: 80 | G17: mA | H17: Y | I17: ILDO3V3_LIM | J17: =IF(I17<>"",VLOOKUP(I17,'Test Item'!C:H,2,0),"") -> 70 | K17: =IF(I17<>"",VLOOKUP(I17,'Test Item'!C:H,3,0),"") -> 150 | L17: =IF(I17<>"",VLOOKUP(I17,'Test Item'!C:H,4,0),"") -> mA
A18: VLDO3V3_POK | B18: LDO3V3 POK(NOTE1) | C18: Rising for LDO3V3 POK=H | D18: 2.35 | E18: 2.5 | F18: 2.65 | G18: V | H18: GBD | J18: =IF(I18<>"",VLOOKUP(I18,'Test Item'!C:H,2,0),"") | K18: =IF(I18<>"",VLOOKUP(I18,'Test Item'!C:H,3,0),"") | L18: =IF(I18<>"",VLOOKUP(I18,'Test Item'!C:H,4,0),"")
A19: VLDO3V3_POK_HYS | B19: LDO3V3 POK Hysteresis | C19: Falling | E19: 200 | G19: mV | H19: GBD | J19: =IF(I19<>"",VLOOKUP(I19,'Test Item'!C:H,2,0),"") | K19: =IF(I19<>"",VLOOKUP(I19,'Test Item'!C:H,3,0),"") | L19: =IF(I19<>"",VLOOKUP(I19,'Test Item'!C:H,4,0),"")
A20: Internal Switch (SW) between VIN_3V3 and LDO3V3 | J20: =IF(I20<>"",VLOOKUP(I20,'Test Item'!C:H,2,0),"") | K20: =IF(I20<>"",VLOOKUP(I20,'Test Item'!C:H,3,0),"") | L20: =IF(I20<>"",VLOOKUP(I20,'Test Item'!C:H,4,0),"")
A21: RDS_ON_SW | B21: Internal switch ON resistance between VIN_3V3 and LDO3V3 | C21: VIN_3V3=3.3V, ILOAD=50mA, including bonding wire resistance | E21: 1.9 | F21: 3 | G21: Ω | H21: Y | I21: INTERNAL_SW_ON_RES | J21: =IF(I21<>"",VLOOKUP(I21,'Test Item'!C:H,2,0),"") -> 1.4 | K21: =IF(I21<>"",VLOOKUP(I21,'Test Item'!C:H,3,0),"") -> 2.9 | L21: =IF(I21<>"",VLOOKUP(I21,'Test Item'!C:H,4,0),"") -> Ohm
A22: VSW_REG | B22: The switch regulation from VIN_3V3 | C22: VIN_3V3 ≥ 3.15V at 1mA & VBUS_P0/P1=0V | E22: 10 | G22: mV | H22: Y | I22: VIN3V3_REG | J22: =IF(I22<>"",VLOOKUP(I22,'Test Item'!C:H,2,0),"") -> 5 | K22: =IF(I22<>"",VLOOKUP(I22,'Test Item'!C:H,3,0),"") -> 20 | L22: =IF(I22<>"",VLOOKUP(I22,'Test Item'!C:H,4,0),"") -> mV
A23: Thermal Protection | H23: Y | J23: =IF(I23<>"",VLOOKUP(I23,'Test Item'!C:H,2,0),"") | K23: =IF(I23<>"",VLOOKUP(I23,'Test Item'!C:H,3,0),"") | L23: =IF(I23<>"",VLOOKUP(I23,'Test Item'!C:H,4,0),"") | N23: =IF(D23<>"",J23-D23,"") | O23: =IF(F23<>"",F23-K23,"")
A24: TSHDN(NOTE1) | B24: Thermal Shutdown | C24: Rising to disable all the switches (SNK_CTL_P0/P1 output, Source, VCONN, CC & SBU SW) or & LDO3V3 regulator | E24: 135 | G24: °C | H24: Y | I24: THSD0_RISE | J24: =IF(I24<>"",VLOOKUP(I24,'Test Item'!C:H,2,0),"") -> 500 | K24: =IF(I24<>"",VLOOKUP(I24,'Test Item'!C:H,3,0),"") -> 540 | L24: =IF(I24<>"",VLOOKUP(I24,'Test Item'!C:H,4,0),"") -> mV | M24: 测了THSD的对应的二极管电压 | N24: =IF(D24<>"",J24-D24,"") | O24: =IF(F24<>"",F24-K24,"")
C25: (except for the internal SW between VIN_3V3 and LDO3V3) | J25: =IF(I25<>"",VLOOKUP(I25,'Test Item'!C:H,2,0),"") | K25: =IF(I25<>"",VLOOKUP(I25,'Test Item'!C:H,3,0),"") | L25: =IF(I25<>"",VLOOKUP(I25,'Test Item'!C:H,4,0),"")
A26: Logic Output (INTB) | H26: Y | J26: =IF(I26<>"",VLOOKUP(I26,'Test Item'!C:H,2,0),"") | K26: =IF(I26<>"",VLOOKUP(I26,'Test Item'!C:H,3,0),"") | L26: =IF(I26<>"",VLOOKUP(I26,'Test Item'!C:H,4,0),"")
A27: VOL | B27: Output Logic Low voltage | C27: IOL=1mA | F27: 0.4 | G27: V | H27: Y | I27: VOL_INTB_1MA | J27: =IF(I27<>"",VLOOKUP(I27,'Test Item'!C:H,2,0),"") -> -0.1 | K27: =IF(I27<>"",VLOOKUP(I27,'Test Item'!C:H,3,0),"") -> 0.1 | L27: =IF(I27<>"",VLOOKUP(I27,'Test Item'!C:H,4,0),"") -> V
A28: RPULLUP_INTB | B28: Internal pull-up resistance | C28: Pull-up to LDO3V3 | E28: 10 | F28: 20 | G28: kΩ | H28: Y | I28: RPULLUP_INTB | J28: =IF(I28<>"",VLOOKUP(I28,'Test Item'!C:H,2,0),"") -> 8 | K28: =IF(I28<>"",VLOOKUP(I28,'Test Item'!C:H,3,0),"") -> 12 | L28: =IF(I28<>"",VLOOKUP(I28,'Test Item'!C:H,4,0),"") -> kOhm
A29: Logic Inputs (FRS_EN_P0, FRS_EN_P1) | H29: Y | J29: =IF(I29<>"",VLOOKUP(I29,'Test Item'!C:H,2,0),"") | K29: =IF(I29<>"",VLOOKUP(I29,'Test Item'!C:H,3,0),"") | L29: =IF(I29<>"",VLOOKUP(I29,'Test Item'!C:H,4,0),"")
A30: VIH | B30: Logic input high threshold | D30: 1.2 | G30: V | H30: Y | I30: VIH_FRS_EN_P0 | J30: =IF(I30<>"",VLOOKUP(I30,'Test Item'!C:H,2,0),"") -> 0.8 | K30: =IF(I30<>"",VLOOKUP(I30,'Test Item'!C:H,3,0),"") -> 1 | L30: =IF(I30<>"",VLOOKUP(I30,'Test Item'!C:H,4,0),"") -> V
A31: VIL | B31: Logic input low threshold | F31: 0.4 | G31: V | H31: Y | I31: VIL_FRS_EN_P0 | J31: =IF(I31<>"",VLOOKUP(I31,'Test Item'!C:H,2,0),"") -> 0.5 | K31: =IF(I31<>"",VLOOKUP(I31,'Test Item'!C:H,3,0),"") -> 0.8 | L31: =IF(I31<>"",VLOOKUP(I31,'Test Item'!C:H,4,0),"") -> V
A32: ILK | B32: Leakage Current | C32: Pull up to LDO3V3 | E32: 3.3 | F32: 5 | G32: µA | H32: Y | I32: ILK_FRS_EN_P0 | J32: =IF(I32<>"",VLOOKUP(I32,'Test Item'!C:H,2,0),"") -> 2 | K32: =IF(I32<>"",VLOOKUP(I32,'Test Item'!C:H,3,0),"") -> 4.8 | L32: =IF(I32<>"",VLOOKUP(I32,'Test Item'!C:H,4,0),"") -> uA
A33: RPD | B33: Pulldown resistance | C33: On each pin | E33: 1 | G33: MΩ | H33: Y | I33: RPD_FRS_EN_P0 | J33: =IF(I33<>"",VLOOKUP(I33,'Test Item'!C:H,2,0),"") -> 0.7 | K33: =IF(I33<>"",VLOOKUP(I33,'Test Item'!C:H,3,0),"") -> 1.3 | L33: =IF(I33<>"",VLOOKUP(I33,'Test Item'!C:H,4,0),"") -> M
A34: High or Low Voltage Output on SNK_CTL_P0 and SNK_CTL_P1 | J34: =IF(I34<>"",VLOOKUP(I34,'Test Item'!C:H,2,0),"") | K34: =IF(I34<>"",VLOOKUP(I34,'Test Item'!C:H,3,0),"") | L34: =IF(I34<>"",VLOOKUP(I34,'Test Item'!C:H,4,0),"")
A35: VSNK_CTL_P0_P1 | B35: High voltage output range | C35: SNK_CTL_GDRV_P0/P1=1b (high voltage output) in SNK_CTL_EN_P0/P1=1b | D35: 6 | E35: 8 | G35: V | H35: Y | I35: V_SNK_CTL_P0 | J35: =IF(I35<>"",VLOOKUP(I35,'Test Item'!C:H,2,0),"") -> 35 | K35: =IF(I35<>"",VLOOKUP(I35,'Test Item'!C:H,3,0),"") -> 39.8 | L35: =IF(I35<>"",VLOOKUP(I35,'Test Item'!C:H,4,0),"") -> V | M35: 测的是VBUS=28V下的SNK_CTL电压
A36: ISNK_CTL_P0_1 | B36: Sourcing current in high voltage output | C36: SNK_CTL_GDRV_P0/P1=1b (high voltage output) at VBUS_P0/1=5V | E36: 10 | F36: 20 | G36: µA | H36: Y | I36: I_SNK_CTL_P0_H | J36: =IF(I36<>"",VLOOKUP(I36,'Test Item'!C:H,2,0),"") -> 8 | K36: =IF(I36<>"",VLOOKUP(I36,'Test Item'!C:H,3,0),"") -> 18 | L36: =IF(I36<>"",VLOOKUP(I36,'Test Item'!C:H,4,0),"") -> uA
A37: ISNK_CTL_P0_1 | B37: Sourcing current in low voltage output | C37: SNK_CTL_GDRV_P0/P1=0b (low voltage output) | D37: 80 | E37: 100 | G37: µA | H37: Y | I37: VOL_SNK_CTL_P1_100UA | J37: =IF(I37<>"",VLOOKUP(I37,'Test Item'!C:H,2,0),"") -> -0.05 | K37: =IF(I37<>"",VLOOKUP(I37,'Test Item'!C:H,3,0),"") -> 0.05 | L37: =IF(I37<>"",VLOOKUP(I37,'Test Item'!C:H,4,0),"") -> V | M37: 测其在100uA下的电压。显示为低即可
A38: tSNK_CTL_RAMP | B38: SNK_CTL_P0/P1 Ramp Up Time in high voltage output | C38: Programmable, Cg=4nF, VBUS_P0/P1=5V, time from 10% to 90% of SNK_CTL_P0/P1 set to SNK_CTL_GDRV_P0=1b (high voltage output), only effective for an initial startup, 1.75V/ms default | E38: 1.75 | G38: V/ms | H38: GBD | J38: =IF(I38<>"",VLOOKUP(I38,'Test Item'!C:H,2,0),"") | K38: =IF(I38<>"",VLOOKUP(I38,'Test Item'!C:H,3,0),"") | L38: =IF(I38<>"",VLOOKUP(I38,'Test Item'!C:H,4,0),"")
E39: 1.350.93 | H39: GBD | J39: =IF(I39<>"",VLOOKUP(I39,'Test Item'!C:H,2,0),"") | K39: =IF(I39<>"",VLOOKUP(I39,'Test Item'!C:H,3,0),"") | L39: =IF(I39<>"",VLOOKUP(I39,'Test Item'!C:H,4,0),"") | N39: =IF(D39<>"",J39-D39,"")
E40: 0.5 | H40: GBD | J40: =IF(I40<>"",VLOOKUP(I40,'Test Item'!C:H,2,0),"") | K40: =IF(I40<>"",VLOOKUP(I40,'Test Item'!C:H,3,0),"") | L40: =IF(I40<>"",VLOOKUP(I40,'Test Item'!C:H,4,0),"") | N40: =IF(D40<>"",J40-D40,"")
...

Sheet Test Item
A2: Halo Microelectronics Co., Ltd. HL-TE-B10-R02 V05
A3: HL5083A-BD ATE Test Item
A4: 测试程序名称 (ATE test program) | D4: 测试程序释放产线时间 (YY/MM/DD of ATE program released)
A5: HL5083CP00_204KM_A00_V06 | D5: 46139
A6: Test NO. | B6: Sub item | C6: Test Name | D6: Lo | E6: Hi | F6: Unit | G6: LSB | H6: HSB
A7: 1 | B7: 1 | C7: SITE_CK | D7: 0.9 | E7: 1.1 | F7: DB | G7: 5 | H7: 5
A8: =IF(B8=1, MAX(A7:A$7)+1, A7) -> 1 | B8: 2 | C8: BD_CK | D8: 1 | E8: 8 | F8: DB | G8: 5 | H8: 5
A9: =IF(B8=1, MAX(A$7:A8)+1, A8) -> 1 | B9: 3 | C9: PARTNAME | D9: 5083 | E9: 5083 | F9: DB | G9: 5 | H9: 5
A10: =IF(B9=1, MAX(A$7:A9)+1, A9) -> 1 | B10: 4 | C10: DIE_VERSION | D10: 203 | E10: 203 | F10: DB | G10: 5 | H10: 5
A11: =IF(B10=1, MAX(A$7:A10)+1, A10) -> 1 | B11: 5 | C11: SCAN_LOAD | D11: 0 | E11: 0 | F11: DB | G11: 5 | H11: 5
A12: =IF(B11=1, MAX(A$7:A11)+1, A11) -> 1 | B12: 1 | C12: OS_SHORT | D12: 0 | E12: 0 | F12: DB | G12: 6 | H12: 6
A13: =IF(B12=1, MAX(A$7:A12)+1, A12) -> 2 | B13: 2 | C13: OS_SOME_OPEN | D13: 0 | E13: 0 | F13: DB | G13: 5 | H13: 5
A14: =IF(B13=1, MAX(A$7:A13)+1, A13) -> 2 | B14: 3 | C14: OS_ALL_OPEN | D14: 0 | E14: 0 | F14: DB | G14: 5 | H14: 5
A15: =IF(B14=1, MAX(A$7:A14)+1, A14) -> 2 | B15: 4 | C15: OS_VBUS_P0 | D15: -0.676 | E15: -0.476 | F15: V | G15: 5 | H15: 5
A16: =IF(B15=1, MAX(A$7:A15)+1, A15) -> 2 | B16: 5 | C16: OS_CC1_P0 | D16: -0.722 | E16: -0.522 | F16: V | G16: 5 | H16: 5
A17: =IF(B16=1, MAX(A$7:A16)+1, A16) -> 2 | B17: 6 | C17: OS_CC2_P0 | D17: -0.722 | E17: -0.522 | F17: V | G17: 5 | H17: 5
A18: =IF(B17=1, MAX(A$7:A17)+1, A17) -> 2 | B18: 7 | C18: OS_SBU1_P0 | D18: -0.723 | E18: -0.523 | F18: V | G18: 5 | H18: 5
A19: =IF(B18=1, MAX(A$7:A18)+1, A18) -> 2 | B19: 8 | C19: OS_SBU2_P0 | D19: -0.723 | E19: -0.523 | F19: V | G19: 5 | H19: 5
A20: =IF(B19=1, MAX(A$7:A19)+1, A19) -> 2 | B20: 9 | C20: OS_SBU_OVP_P0 | D20: -0.726 | E20: -0.526 | F20: V | G20: 5 | H20: 5
... A260: =IF(B259=1, MAX(A$7:A259)+1, A259) -> 4 | B260: 156 | C260: AMR_DELTA_INTB | D260: -5 | E260: 5 | F260: uA | G260: 10 | H260: 10
A261: =IF(B260=1, MAX(A$7:A260)+1, A260) -> 4 | B261: 157 | C261: AMR_DELTA_LDO3V3 | F261: uA | G261: 10 | H261: 10
A262: =IF(B261=1, MAX(A$7:A261)+1, A261) -> 4 | B262: 158 | C262: AMR_DELTA_VIN_3V3 | D262: -3 | E262: 3 | F262: uA | G262: 10 | H262: 10
A263: =IF(B262=1, MAX(A$7:A262)+1, A262) -> 4 | B263: 159 | C263: AMR_DELTA_VDDIO | D263: -1 | E263: 1 | F263: uA | G263: 10 | H263: 10
A264: =IF(B263=1, MAX(A$7:A263)+1, A263) -> 4 | B264: 160 | C264: AMR_DELTA_PA_20V5A_OFF | D264: -1 | E264: 1 | F264: uA | G264: 10 | H264: 10
A265: =IF(B264=1, MAX(A$7:A264)+1, A264) -> 4 | B265: 161 | C265: AMR_DELTA_PB_20V5A_OFF | D265: -1 | E265: 1 | F265: uA | G265: 10 | H265: 10
A266: =IF(B265=1, MAX(A$7:A265)+1, A265) -> 4 | B266: 162 | C266: AMR_DELTA_VBUS_DIV_P0 | D266: -3 | E266: 3 | F266: uA | G266: 10 | H266: 10
A267: =IF(B266=1, MAX(A$7:A266)+1, A266) -> 4 | B267: 163 | C267: AMR_DELTA_VBUS_DIV_P1 | D267: -3 | E267: 3 | F267: uA | G267: 10 | H267: 10
A268: =IF(B267=1, MAX(A$7:A267)+1, A267) -> 4 | B268: 164 | C268: AMR_DELTA_SRC_CUR_P0 | D268: -1 | E268: 1 | F268: uA | G268: 10 | H268: 10
A269: =IF(B268=1, MAX(A$7:A268)+1, A268) -> 4 | B269: 165 | C269: AMR_DELTA_SRC_CUR_P1 | D269: -1 | E269: 1 | F269: uA | G269: 10 | H269: 10
A270: =IF(B269=1, MAX(A$7:A269)+1, A269) -> 4 | B270: 166 | C270: AMR_DELTA_SBU_OVP_P1 | D270: -1 | E270: 1 | F270: uA | G270: 10 | H270: 10
A271: =IF(B270=1, MAX(A$7:A270)+1, A270) -> 4 | B271: 167 | C271: AMR_DELTA_SBU_OVP_P0 | D271: -1 | E271: 1 | F271: uA | G271: 10 | H271: 10
A272: =IF(B271=1, MAX(A$7:A271)+1, A271) -> 4 | B272: 168 | C272: AMR_DELTA_V5V_DIV | D272: -40 | E272: 40 | F272: uA | G272: 10 | H272: 10
A273: =IF(B272=1, MAX(A$7:A272)+1, A272) -> 4 | B273: 169 | C273: AMR_PRE_SNK_CTL_P0 | D273: 6 | E273: 22 | F273: uA | G273: 10 | H273: 10
... A752: =IF(B751=1, MAX(A$7:A751)+1, A751) -> 44 | B752: 72 | C752: AMR_DELTA2_INTB | D752: -5 | E752: 5 | F752: uA | G752: 31 | H752: 31
A753: =IF(B752=1, MAX(A$7:A752)+1, A752) -> 44 | B753: 73 | C753: AMR_DELTA2_LDO3V3 | F753: uA | G753: 31 | H753: 31
A754: =IF(B753=1, MAX(A$7:A753)+1, A753) -> 44 | B754: 74 | C754: AMR_DELTA2_VIN_3V3 | D754: -100 | E754: 100 | F754: uA | G754: 31 | H754: 31
A755: =IF(B754=1, MAX(A$7:A754)+1, A754) -> 44 | B755: 75 | C755: AMR_DELTA2_VDDIO | D755: -1 | E755: 1 | F755: uA | G755: 31 | H755: 31
A756: =IF(B755=1, MAX(A$7:A755)+1, A755) -> 44 | B756: 76 | C756: AMR_DELTA2_PA_20V5A_OFF | D756: -1 | E756: 1 | F756: uA | G756: 31 | H756: 31
A757: =IF(B756=1, MAX(A$7:A756)+1, A756) -> 44 | B757: 77 | C757: AMR_DELTA2_PB_20V5A_OFF | D757: -1 | E757: 1 | F757: uA | G757: 31 | H757: 31
A758: =IF(B757=1, MAX(A$7:A757)+1, A757) -> 44 | B758: 78 | C758: AMR_DELTA2_VBUS_DIV_P0 | D758: -3 | E758: 3 | F758: uA | G758: 31 | H758: 31
...

Sheet Bin Information
A2: Halo Microelectronics Co., Ltd. HL-TE-B10-R02 V05
A3: HL5083A-BD ATE Test Item
A4: SW Bin | B4: HW Bin | C4: P/F/A | D4: Description | E4: SBL Control
A5: 1 | B5: 1 | C5: P | D5: Pass_Default
A6: 2 | B6: 2 | C6: P | D6: PASS_DPAT
A7: 3 | B7: 3 | C7: F | D7: DPAT_FAIL
A8: 4 | B8: 4 | C8: F | D8: QA_FAIL
A9: 5 | B9: 5 | C9: F | D9: OS_OPEN
A10: 6 | B10: 6 | C10: F | D10: OS_SHORT
A11: 7 | B11: 7 | C11: F | D11: P2P_VBUS_P0_AllFail
A12: 8 | B12: 8 | C12: F | D12: OTP_INIT
A13: 9 | B13: 9 | C13: F | D13: REG_55AA
A14: 10 | B14: 10 | C14: F | D14: AMR_PRE_LKG
A15: 11 | B15: 11 | C15: F | D15: AMR_LKG
A16: 12 | B16: 12 | C16: F | D16: TRIM_VBG_IREF_OSC_LDO
... A34: 33 | B34: 33 | C34: F | D34: POST_OS
